Workbook
Name IQ_CH: 110000
Name IQ_CQ: 5000
Name IQ_CY: 10000
Name IQ_DAILY: 500000
Name IQ_FH: 100000
Name IQ_FQ: 500
Name IQ_FY: 1000
Name IQ_LTM: 2000
Name IQ_MONTH: 15000
Name IQ_NTM: 6000
Name IQ_WEEK: 50000
Name IQ_YTD: 3000
Name UPDATE: 'Data Sheet'!$E$1

Sheet HistoricalFS
B2: ="Historical Financial Statement - "&'Data Sheet'!B1 -> Historical Financial Statement - TATA CONSULTANCY SERVICES LTD
B3: Years | C3: ='Data Sheet'!B16 -> 42460 | D3: ='Data Sheet'!C16 -> 42825 | E3: ='Data Sheet'!D16 -> 43190 | F3: ='Data Sheet'!E16 -> 43555 | G3: ='Data Sheet'!F16 -> 43921 | H3: ='Data Sheet'!G16 -> 44286 | I3: ='Data Sheet'!H16 -> 44651 | J3: ='Data Sheet'!I16 -> 45016 | ... L3: ='Data Sheet'!K16 -> 45747 | M3: LTM
A5: # | B5: Income Statement
B6: Sales | C6: =IFERROR('Data Sheet'!B17,0) -> 108646 | D6: =IFERROR('Data Sheet'!C17,0) -> 117966 | E6: =IFERROR('Data Sheet'!D17,0) -> 123104 | F6: =IFERROR('Data Sheet'!E17,0) -> 146463 | G6: =IFERROR('Data Sheet'!F17,0) -> 156949 | H6: =IFERROR('Data Sheet'!G17,0) -> 164177 | I6: =IFERROR('Data Sheet'!H17,0) -> 191754 | J6: =IFERROR('Data Sheet'!I17,0) -> 225458 | ... L6: =IFERROR('Data Sheet'!K17,0) -> 255324 | M6: =IFERROR(SUM('Data Sheet'!H42:K42),0) -> 257688
B7: Sales Growth | C7: - | D7: =D6/C6-1 -> 0.085783186 | E7: =E6/D6-1 -> 0.043554923 | F7: =F6/E6-1 -> 0.18975013 | G7: =G6/F6-1 -> 0.071594874 | H7: =H6/G6-1 -> 0.046053177 | I7: =I6/H6-1 -> 0.16797115 | J7: =J6/I6-1 -> 0.17576687 | K7: =K6/J6-1 -> 0.068460645 | ... M7: =M6/L6-1 -> 0.0092588241
B9: COGS | C9: =IFERROR(SUM('Data Sheet'!B18,'Data Sheet'!B20:B22)-1*'Data Sheet'!B19,0) -> 57919 | D9: =IFERROR(SUM('Data Sheet'!C18,'Data Sheet'!C20:C22)-1*'Data Sheet'!C19,0) -> 64429 | E9: =IFERROR(SUM('Data Sheet'!D18,'Data Sheet'!D20:D22)-1*'Data Sheet'!D19,0) -> 69096 | F9: =IFERROR(SUM('Data Sheet'!E18,'Data Sheet'!E20:E22)-1*'Data Sheet'!E19,0) -> 80516 | G9: =IFERROR(SUM('Data Sheet'!F18,'Data Sheet'!F20:F22)-1*'Data Sheet'!F19,0) -> 87857 | H9: =IFERROR(SUM('Data Sheet'!G18,'Data Sheet'!G20:G22)-1*'Data Sheet'!G19,0) -> 93276 | I9: =IFERROR(SUM('Data Sheet'!H18,'Data Sheet'!H20:H22)-1*'Data Sheet'!H19,0) -> 108717 | J9: =IFERROR(SUM('Data Sheet'!I18,'Data Sheet'!I20:I22)-1*'Data Sheet'!I19,0) -> 129403 | ... L9: =IFERROR(SUM('Data Sheet'!K18,'Data Sheet'!K20:K22)-1*'Data Sheet'!K19,0) -> 157436 | M9: =IFERROR(SUM('Data Sheet'!H43:K43),0) -> 188821
B10: COGS % Sales | C10: =C9/C6 -> 0.53309832 | D10: =D9/D6 -> 0.54616584 | E10: =E9/E6 -> 0.56128152 | F10: =F9/F6 -> 0.54973611 | G10: =G9/G6 -> 0.55978057 | H10: =H9/H6 -> 0.56814292 | I10: =I9/I6 -> 0.56696079 | J10: =J9/J6 -> 0.57395612 | ... M10: =M9/M6 -> 0.73275046
B12: Gross Profit | C12: =C6-C9 -> 50727 | D12: =D6-D9 -> 53537 | E12: =E6-E9 -> 54008 | F12: =F6-F9 -> 65947 | G12: =G6-G9 -> 69092 | H12: =H6-H9 -> 70901 | I12: =I6-I9 -> 83037 | J12: =J6-J9 -> 96055 | ... M12: =M6-M9 -> 68867
B13: Gross Margins | C13: =C12/C6 -> 0.46690168 | D13: =D12/D6 -> 0.45383416 | E13: =E12/E6 -> 0.43871848 | F13: =F12/F6 -> 0.45026389 | G13: =G12/G6 -> 0.44021943 | H13: =H12/H6 -> 0.43185708 | I13: =I12/I6 -> 0.43303921 | J13: =J12/J6 -> 0.42604388 | ... M13: =M12/M6 -> 0.26724954
B15: Selling & General Expenses | C15: =IFERROR(SUM('Data Sheet'!B23:B24),0) -> 20050 | D15: =IFERROR(SUM('Data Sheet'!C23:C24),0) -> 21226 | E15: =IFERROR(SUM('Data Sheet'!D23:D24),0) -> 21492 | F15: =IFERROR(SUM('Data Sheet'!E23:E24),0) -> 26441 | G15: =IFERROR(SUM('Data Sheet'!F23:F24),0) -> 26983 | H15: =IFERROR(SUM('Data Sheet'!G23:G24),0) -> 24355 | I15: =IFERROR(SUM('Data Sheet'!H23:H24),0) -> 29980 | J15: =IFERROR(SUM('Data Sheet'!I23:I24),0) -> 36796 | ... L15: =IFERROR(SUM('Data Sheet'!K23:K24),0) -> 30481
B16: S&G Exp % Sales | C16: =C15/C6 -> 0.1845443 | D16: =D15/D6 -> 0.1799332 | E16: =E15/E6 -> 0.17458409 | F16: =F15/F6 -> 0.18053024 | G16: =G15/G6 -> 0.17192209 | H16: =H15/H6 -> 0.14834599 | I16: =I15/I6 -> 0.15634615 | J16: =J15/J6 -> 0.16320556 | ... M16: =M15/M6 -> 0
B18: EBITDA | C18: =C12-C15 -> 30677 | D18: =D12-D15 -> 32311 | E18: =E12-E15 -> 32516 | F18: =F12-F15 -> 39506 | G18: =G12-G15 -> 42109 | H18: =H12-H15 -> 46546 | I18: =I12-I15 -> 53057 | J18: =J12-J15 -> 59259 | ... L18: =L12-L15 -> 67407 | M18: =IFERROR(SUM('Data Sheet'!H51:K51),0) -> 72282
B19: EBITDA Margins | C19: =C18/C6 -> 0.28235738 | D19: =D18/D6 -> 0.27390095 | E19: =E18/E6 -> 0.26413439 | F19: =F18/F6 -> 0.26973365 | G19: =G18/G6 -> 0.26829734 | H19: =H18/H6 -> 0.28351109 | I19: =I18/I6 -> 0.27669305 | J19: =J18/J6 -> 0.26283831 | ... M19: =M18/M6 -> 0.280502
B21: Interest | C21: =IFERROR('Data Sheet'!B27,0) -> 33 | D21: =IFERROR('Data Sheet'!C27,0) -> 32 | E21: =IFERROR('Data Sheet'!D27,0) -> 52 | F21: =IFERROR('Data Sheet'!E27,0) -> 198 | G21: =IFERROR('Data Sheet'!F27,0) -> 924 | H21: =IFERROR('Data Sheet'!G27,0) -> 637 | I21: =IFERROR('Data Sheet'!H27,0) -> 784 | J21: =IFERROR('Data Sheet'!I27,0) -> 779 | ... L21: =IFERROR('Data Sheet'!K27,0) -> 796 | M21: =IFERROR(SUM('Data Sheet'!H46:K46),0) -> 885
B22: Interest % Sales | C22: =C21/C6 -> 0.00030373875 | D22: =D21/D6 -> 0.0002712646 | E22: =E21/E6 -> 0.00042240707 | F22: =F21/F6 -> 0.0013518773 | G22: =G21/G6 -> 0.0058872627 | H22: =H21/H6 -> 0.0038799588 | I22: =I21/I6 -> 0.0040885718 | J22: =J21/J6 -> 0.003455189 | ... M22: =M21/M6 -> 0.0034343858
B24: Depreciation | C24: =IFERROR('Data Sheet'!B26,0) -> 1888 | D24: =IFERROR('Data Sheet'!C26,0) -> 1987 | E24: =IFERROR('Data Sheet'!D26,0) -> 2014 | F24: =IFERROR('Data Sheet'!E26,0) -> 2056 | G24: =IFERROR('Data Sheet'!F26,0) -> 3529 | H24: =IFERROR('Data Sheet'!G26,0) -> 4065 | I24: =IFERROR('Data Sheet'!H26,0) -> 4604 | J24: =IFERROR('Data Sheet'!I26,0) -> 5022 | ... L24: =IFERROR('Data Sheet'!K26,0) -> 5242 | M24: =IFERROR(SUM('Data Sheet'!H45:K45),0) -> 5530
B25: Depreciation%Sales | C25: =C24/C6 -> 0.017377538 | D25: =D24/D6 -> 0.016843836 | E25: =E24/E6 -> 0.016360151 | F25: =F24/F6 -> 0.014037675 | G25: =G24/G6 -> 0.022485011 | H25: =H24/H6 -> 0.024759863 | I25: =I24/I6 -> 0.024009929 | J25: =J24/J6 -> 0.022274659 | ... M25: =M24/M6 -> 0.02146006
B27: Earnings Before Tax | C27: =IFERROR(C18-SUM(C24,C21),0) -> 28756 | D27: =IFERROR(D18-SUM(D24,D21),0) -> 30292 | E27: =IFERROR(E18-SUM(E24,E21),0) -> 30450 | F27: =IFERROR(F18-SUM(F24,F21),0) -> 37252 | G27: =IFERROR(G18-SUM(G24,G21),0) -> 37656 | H27: =IFERROR(H18-SUM(H24,H21),0) -> 41844 | I27: =IFERROR(I18-SUM(I24,I21),0) -> 47669 | J27: =IFERROR(J18-SUM(J24,J21),0) -> 53458 | ... M27: =IFERROR(M18-SUM(M24,M21),0) -> 65867
B28: EBT % Sales | C28: =C27/C6 -> 0.2646761 | D28: =D27/D6 -> 0.25678585 | E28: =E27/E6 -> 0.24735183 | F28: =F27/F6 -> 0.2543441 | G28: =G27/G6 -> 0.23992507 | H28: =H27/H6 -> 0.25487127 | I28: =I27/I6 -> 0.24859455 | J28: =J27/J6 -> 0.23710846 | ... M28: =M27/M6 -> 0.25560756
B30: Tax | C30: =IFERROR('Data Sheet'!B29,0) -> 7502 | D30: =IFERROR('Data Sheet'!C29,0) -> 8156 | E30: =IFERROR('Data Sheet'!D29,0) -> 8212 | F30: =IFERROR('Data Sheet'!E29,0) -> 10001 | G30: =IFERROR('Data Sheet'!F29,0) -> 9801 | H30: =IFERROR('Data Sheet'!G29,0) -> 11198 | I30: =IFERROR('Data Sheet'!H29,0) -> 13238 | J30: =IFERROR('Data Sheet'!I29,0) -> 14604 | ... L30: =IFERROR('Data Sheet'!K29,0) -> 16534 | M30: =IFERROR(SUM('Data Sheet'!H48:K48),0) -> 16428
B31: Effective Tax Rate | C31: =C30/C27 -> 0.26088468 | D31: =D30/D27 -> 0.26924601 | E31: =E30/E27 -> 0.26968801 | F31: =F30/F27 -> 0.26846881 | G31: =G30/G27 -> 0.26027725 | H31: =H30/H27 -> 0.26761304 | I31: =I30/I27 -> 0.27770669 | J31: =J30/J27 -> 0.27318643 | ... M31: =M30/M27 -> 0.24941169
B33: Net Profit | C33: =IFERROR(C27-C30,0) -> 21254 | D33: =IFERROR(D27-D30,0) -> 22136 | E33: =IFERROR(E27-E30,0) -> 22238 | F33: =IFERROR(F27-F30,0) -> 27251 | G33: =IFERROR(G27-G30,0) -> 27855 | H33: =IFERROR(H27-H30,0) -> 30646 | I33: =IFERROR(I27-I30,0) -> 34431 | J33: =IFERROR(J27-J30,0) -> 38854 | ... M33: =IFERROR(M27-M30,0) -> 49439
B34: Net Margins | C34: =C33/C6 -> 0.19562616 | D34: =D33/D6 -> 0.18764729 | E34: =E33/E6 -> 0.18064401 | F34: =F33/F6 -> 0.18606064 | G34: =G33/G6 -> 0.17747803 | H34: =H33/H6 -> 0.18666439 | I34: =I33/I6 -> 0.17955818 | J34: =J33/J6 -> 0.17233365 | ... M34: =M33/M6 -> 0.19185604
B36: No of Equity Shares | C36: =IFERROR('Data Sheet'!B93,0) -> 394.09 | D36: =IFERROR('Data Sheet'!C93,0) -> 394.09 | E36: =IFERROR('Data Sheet'!D93,0) -> 382.86 | F36: =IFERROR('Data Sheet'!E93,0) -> 375.24 | G36: =IFERROR('Data Sheet'!F93,0) -> 375.24 | H36: =IFERROR('Data Sheet'!G93,0) -> 369.91 | I36: =IFERROR('Data Sheet'!H93,0) -> 365.91 | J36: =IFERROR('Data Sheet'!I93,0) -> 365.91 | ... L36: =IFERROR('Data Sheet'!K93,0) -> 361.81 | M36: =L36 -> 361.81
B38: Earnings per Share | C38: =IFERROR(C33/C36,0) -> 53.931843 | D38: =IFERROR(D33/D36,0) -> 56.16991 | E38: =IFERROR(E33/E36,0) -> 58.083895 | F38: =IFERROR(F33/F36,0) -> 72.622855 | G38: =IFERROR(G33/G36,0) -> 74.232491 | H38: =IFERROR(H33/H36,0) -> 82.847179 | I38: =IFERROR(I33/I36,0) -> 94.096909 | J38: =IFERROR(J33/J36,0) -> 106.18458 | ... M38: =IFERROR(M33/M36,0) -> 136.64354
B39: EPS Growth % | D39: =IFERROR(D38/C38-1,0) -> 0.041498071 | E39: =IFERROR(E38/D38-1,0) -> 0.034074907 | F39: =IFERROR(F38/E38-1,0) -> 0.25030966 | G39: =IFERROR(G38/F38-1,0) -> 0.022164324 | H39: =IFERROR(H38/G38-1,0) -> 0.1160501 | I39: =IFERROR(I38/H38-1,0) -> 0.13578893 | J39: =IFERROR(J38/I38-1,0) -> 0.12845982 | K39: =IFERROR(K38/J38-1,0) -> 0.10974768 | ... M39: =IFERROR(M38/L38-1,0) -> 0.10268763
B41: Dividend per Share | C41: =IFERROR('Data Sheet'!B31/HistoricalFS!C36,0) -> 21.745033 | D41: =IFERROR('Data Sheet'!C31/HistoricalFS!D36,0) -> 23.494633 | E41: =IFERROR('Data Sheet'!D31/HistoricalFS!E36,0) -> 24.943844 | F41: =IFERROR('Data Sheet'!E31/HistoricalFS!F36,0) -> 29.980812 | G41: =IFERROR('Data Sheet'!F31/HistoricalFS!G36,0) -> 72.95331 | H41: =IFERROR('Data Sheet'!G31/HistoricalFS!H36,0) -> 38.009245 | I41: =IFERROR('Data Sheet'!H31/HistoricalFS!I36,0) -> 43.010576 | J41: =IFERROR('Data Sheet'!I31/HistoricalFS!J36,0) -> 115.02829 | ... M41: =IFERROR('Data Sheet'!L31/HistoricalFS!M36,0) -> 0
B42: Dividend payout ratio | C42: =IFERROR(C41/C38,0) -> 0.40319469 | D42: =IFERROR(D41/D38,0) -> 0.41827792 | E42: =IFERROR(E41/E38,0) -> 0.42944509 | F42: =IFERROR(F41/F38,0) -> 0.41282889 | G42: =IFERROR(G41/G38,0) -> 0.98276791 | H42: =IFERROR(H41/H38,0) -> 0.45878744 | I42: =IFERROR(I41/I38,0) -> 0.45708809 | J42: =IFERROR(J41/J38,0) -> 1.0832861 | ... M42: =IFERROR(M41/M38,0) -> 0
B44: Retained Earnings | C44: =IFERROR(IF(C38>C41,1-C42,0),0) -> 0.59680531 | D44: =IFERROR(IF(D38>D41,1-D42,0),0) -> 0.58172208 | E44: =IFERROR(IF(E38>E41,1-E42,0),0) -> 0.57055491 | F44: =IFERROR(IF(F38>F41,1-F42,0),0) -> 0.58717111 | G44: =IFERROR(IF(G38>G41,1-G42,0),0) -> 0.017232095 | H44: =IFERROR(IF(H38>H41,1-H42,0),0) -> 0.54121256 | I44: =IFERROR(IF(I38>I41,1-I42,0),0) -> 0.54291191 | J44: =IFERROR(IF(J38>J41,1-J42,0),0) -> 0 | ... M44: =IFERROR(IF(M38>M41,1-M42,0),0) -> 1
A46: # | B46: Balance Sheet
B47: Equity Share Capital | C47: =IFERROR('Data Sheet'!B57,0) -> 197 | D47: =IFERROR('Data Sheet'!C57,0) -> 197 | E47: =IFERROR('Data Sheet'!D57,0) -> 191 | F47: =IFERROR('Data Sheet'!E57,0) -> 375 | G47: =IFERROR('Data Sheet'!F57,0) -> 375 | H47: =IFERROR('Data Sheet'!G57,0) -> 370 | I47: =IFERROR('Data Sheet'!H57,0) -> 366 | J47: =IFERROR('Data Sheet'!I57,0) -> 366 | ... L47: =IFERROR('Data Sheet'!K57,0) -> 362
B48: Reserves | C48: =IFERROR('Data Sheet'!B58,0) -> 70875 | D48: =IFERROR('Data Sheet'!C58,0) -> 86017 | E48: =IFERROR('Data Sheet'!D58,0) -> 84937 | F48: =IFERROR('Data Sheet'!E58,0) -> 89071 | G48: =IFERROR('Data Sheet'!F58,0) -> 83751 | H48: =IFERROR('Data Sheet'!G58,0) -> 86063 | I48: =IFERROR('Data Sheet'!H58,0) -> 88773 | J48: =IFERROR('Data Sheet'!I58,0) -> 90058 | ... L48: =IFERROR('Data Sheet'!K58,0) -> 94394
B49: Borrowings | C49: =IFERROR('Data Sheet'!B59,0) -> 245 | D49: =IFERROR('Data Sheet'!C59,0) -> 289 | E49: =IFERROR('Data Sheet'!D59,0) -> 247 | F49: =IFERROR('Data Sheet'!E59,0) -> 62 | G49: =IFERROR('Data Sheet'!F59,0) -> 8174 | H49: =IFERROR('Data Sheet'!G59,0) -> 7795 | I49: =IFERROR('Data Sheet'!H59,0) -> 7818 | J49: =IFERROR('Data Sheet'!I59,0) -> 7688 | ... L49: =IFERROR('Data Sheet'!K59,0) -> 9392
B50: Other Liabilities | C50: =IFERROR('Data Sheet'!B60,0) -> 16974 | D50: =IFERROR('Data Sheet'!C60,0) -> 15830 | E50: =IFERROR('Data Sheet'!D60,0) -> 19751 | F50: =IFERROR('Data Sheet'!E60,0) -> 24393 | G50: =IFERROR('Data Sheet'!F60,0) -> 27827 | H50: =IFERROR('Data Sheet'!G60,0) -> 35764 | I50: =IFERROR('Data Sheet'!H60,0) -> 43967 | J50: =IFERROR('Data Sheet'!I60,0) -> 44747 | ... L50: =IFERROR('Data Sheet'!K60,0) -> 54501
B51: Total Liabilities | C51: =IFERROR('Data Sheet'!B61,0) -> 88291 | D51: =IFERROR('Data Sheet'!C61,0) -> 102333 | E51: =IFERROR('Data Sheet'!D61,0) -> 105126 | F51: =IFERROR('Data Sheet'!E61,0) -> 113901 | G51: =IFERROR('Data Sheet'!F61,0) -> 120127 | H51: =IFERROR('Data Sheet'!G61,0) -> 129992 | I51: =IFERROR('Data Sheet'!H61,0) -> 140924 | J51: =IFERROR('Data Sheet'!I61,0) -> 142859 | ... L51: =IFERROR('Data Sheet'!K61,0) -> 158649
B53: Fixed Assets Net Block | C53: =IFERROR('Data Sheet'!B62,0) -> 11774 | D53: =IFERROR('Data Sheet'!C62,0) -> 11701 | E53: =IFERROR('Data Sheet'!D62,0) -> 11973 | F53: =IFERROR('Data Sheet'!E62,0) -> 12290 | G53: =IFERROR('Data Sheet'!F62,0) -> 20928 | H53: =IFERROR('Data Sheet'!G62,0) -> 21021 | I53: =IFERROR('Data Sheet'!H62,0) -> 21298 | J53: =IFERROR('Data Sheet'!I62,0) -> 20515 | ... L53: =IFERROR('Data Sheet'!K62,0) -> 23053
B54: Capital Work in Progress | C54: =IFERROR('Data Sheet'!B63,0) -> 1670 | D54: =IFERROR('Data Sheet'!C63,0) -> 1541 | E54: =IFERROR('Data Sheet'!D63,0) -> 1278 | F54: =IFERROR('Data Sheet'!E63,0) -> 963 | G54: =IFERROR('Data Sheet'!F63,0) -> 906 | H54: =IFERROR('Data Sheet'!G63,0) -> 926 | I54: =IFERROR('Data Sheet'!H63,0) -> 1205 | J54: =IFERROR('Data Sheet'!I63,0) -> 1234 | ... L54: =IFERROR('Data Sheet'!K63,0) -> 1546
B55: Investments | C55: =IFERROR('Data Sheet'!B64,0) -> 22822 | D55: =IFERROR('Data Sheet'!C64,0) -> 41980 | E55: =IFERROR('Data Sheet'!D64,0) -> 36008 | F55: =IFERROR('Data Sheet'!E64,0) -> 29330 | G55: =IFERROR('Data Sheet'!F64,0) -> 26356 | H55: =IFERROR('Data Sheet'!G64,0) -> 29373 | I55: =IFERROR('Data Sheet'!H64,0) -> 30485 | J55: =IFERROR('Data Sheet'!I64,0) -> 37163 | ... L55: =IFERROR('Data Sheet'!K64,0) -> 30964
B56: Other Assets | C56: =IFERROR('Data Sheet'!B65-SUM('Data Sheet'!B67:B69),0) -> 21148 | D56: =IFERROR('Data Sheet'!C65-SUM('Data Sheet'!C67:C69),0) -> 20324 | E56: =IFERROR('Data Sheet'!D65-SUM('Data Sheet'!D67:D69),0) -> 23737 | F56: =IFERROR('Data Sheet'!E65-SUM('Data Sheet'!E67:E69),0) -> 31114 | G56: =IFERROR('Data Sheet'!F65-SUM('Data Sheet'!F67:F69),0) -> 31734 | H56: =IFERROR('Data Sheet'!G65-SUM('Data Sheet'!G67:G69),0) -> 39256 | I56: =IFERROR('Data Sheet'!H65-SUM('Data Sheet'!H67:H69),0) -> 27885 | J56: =IFERROR('Data Sheet'!I65-SUM('Data Sheet'!I67:I69),0) -> 22933 | ... L56: =IFERROR('Data Sheet'!K65-SUM('Data Sheet'!K67:K69),0) -> 28556
B57: Total Non Current Assets | C57: =SUM(C53:C56) -> 57414 | D57: =SUM(D53:D56) -> 75546 | E57: =SUM(E53:E56) -> 72996 | F57: =SUM(F53:F56) -> 73697 | G57: =SUM(G53:G56) -> 79924 | H57: =SUM(H53:H56) -> 90576 | I57: =SUM(I53:I56) -> 80873 | J57: =SUM(J53:J56) -> 81845 | ... L57: =SUM(L53:L56) -> 84119
...

Sheet ratio
A1: .
B3: Ratio Analysis of - TATA CONSULTANCY SERVICES LTD
B4: Years | C4: 42460 | D4: 42825 | E4: 43190 | F4: 43555 | G4: 43921 | H4: 44286 | I4: 44651 | J4: 45016 | K4: 45382 | L4: 45747
B6: SalesGrowth | C6: =HistoricalFS!C7 -> - | D6: =HistoricalFS!D7 -> 0.085783186 | E6: =HistoricalFS!E7 -> 0.043554923 | F6: =HistoricalFS!F7 -> 0.18975013 | G6: =HistoricalFS!G7 -> 0.071594874 | H6: =HistoricalFS!H7 -> 0.046053177 | I6: =HistoricalFS!I7 -> 0.16797115 | J6: =HistoricalFS!J7 -> 0.17576687 | ... L6: =HistoricalFS!L7 -> 0.059906265
B7: GrossMargin | C7: =HistoricalFS!C13 -> 0.46690168 | D7: =HistoricalFS!D13 -> 0.45383416 | E7: =HistoricalFS!E13 -> 0.43871848 | F7: =HistoricalFS!F13 -> 0.45026389 | G7: =HistoricalFS!G13 -> 0.44021943 | H7: =HistoricalFS!H13 -> 0.43185708 | I7: =HistoricalFS!I13 -> 0.43303921 | J7: =HistoricalFS!J13 -> 0.42604388 | ... L7: =HistoricalFS!L13 -> 0.38338738
B8: EBITDA Growth | C8: =HistoricalFS!D18/HistoricalFS!C18-1 -> 0.053264661 | D8: =HistoricalFS!E18/HistoricalFS!D18-1 -> 0.0063445885 | E8: =HistoricalFS!F18/HistoricalFS!E18-1 -> 0.21497109 | F8: =HistoricalFS!G18/HistoricalFS!F18-1 -> 0.065888726 | G8: =HistoricalFS!H18/HistoricalFS!G18-1 -> 0.1053694 | H8: =HistoricalFS!I18/HistoricalFS!H18-1 -> 0.13988313 | I8: =HistoricalFS!J18/HistoricalFS!I18-1 -> 0.11689315 | J8: =HistoricalFS!K18/HistoricalFS!J18-1 -> 0.084999747 | ... L8: =HistoricalFS!M18/HistoricalFS!L18-1 -> 0.072321866
B9: EBIT Growth | C9: =HistoricalFS!D27/HistoricalFS!C27-1 -> 0.053414939 | D9: =HistoricalFS!E27/HistoricalFS!D27-1 -> 0.0052158986 | E9: =HistoricalFS!F27/HistoricalFS!E27-1 -> 0.22338259 | F9: =HistoricalFS!G27/HistoricalFS!F27-1 -> 0.010845055 | G9: =HistoricalFS!H27/HistoricalFS!G27-1 -> 0.11121734 | H9: =HistoricalFS!I27/HistoricalFS!H27-1 -> 0.13920753 | I9: =HistoricalFS!J27/HistoricalFS!I27-1 -> 0.12144161 | J9: =HistoricalFS!K27/HistoricalFS!J27-1 -> 0.094934341 | ... L9: =HistoricalFS!M27/HistoricalFS!L27-1 -> 0.073294334
B10: Net Profit Growth | C10: =HistoricalFS!D33/HistoricalFS!C33-1 -> 0.041498071 | D10: =HistoricalFS!E33/HistoricalFS!D33-1 -> 0.0046078786 | E10: =HistoricalFS!F33/HistoricalFS!E33-1 -> 0.22542495 | F10: =HistoricalFS!G33/HistoricalFS!F33-1 -> 0.022164324 | G10: =HistoricalFS!H33/HistoricalFS!G33-1 -> 0.10019745 | H10: =HistoricalFS!I33/HistoricalFS!H33-1 -> 0.12350715 | I10: =HistoricalFS!J33/HistoricalFS!I33-1 -> 0.12845982 | J10: =HistoricalFS!K33/HistoricalFS!J33-1 -> 0.097313018 | ... L10: =HistoricalFS!M33/HistoricalFS!L33-1 -> 0.10268763
B12: Gross Margin | C12: =HistoricalFS!C13 -> 0.46690168 | D12: =HistoricalFS!D13 -> 0.45383416 | E12: =HistoricalFS!E13 -> 0.43871848 | F12: =HistoricalFS!F13 -> 0.45026389 | G12: =HistoricalFS!G13 -> 0.44021943 | H12: =HistoricalFS!H13 -> 0.43185708 | I12: =HistoricalFS!I13 -> 0.43303921 | J12: =HistoricalFS!J13 -> 0.42604388 | ... L12: =HistoricalFS!L13 -> 0.38338738
B13: EBITDA Margin | C13: =HistoricalFS!C19 -> 0.28235738 | D13: =HistoricalFS!D19 -> 0.27390095 | E13: =HistoricalFS!E19 -> 0.26413439 | F13: =HistoricalFS!F19 -> 0.26973365 | G13: =HistoricalFS!G19 -> 0.26829734 | H13: =HistoricalFS!H19 -> 0.28351109 | I13: =HistoricalFS!I19 -> 0.27669305 | J13: =HistoricalFS!J19 -> 0.26283831 | ... L13: =HistoricalFS!L19 -> 0.26400573
B14: EBT Margin | C14: =HistoricalFS!C28 -> 0.2646761 | D14: =HistoricalFS!D28 -> 0.25678585 | E14: =HistoricalFS!E28 -> 0.24735183 | F14: =HistoricalFS!F28 -> 0.2543441 | G14: =HistoricalFS!G28 -> 0.23992507 | H14: =HistoricalFS!H28 -> 0.25487127 | I14: =HistoricalFS!I28 -> 0.24859455 | J14: =HistoricalFS!J28 -> 0.23710846 | ... L14: =HistoricalFS!L28 -> 0.24035735
B15: Net Profit Margin | C15: =HistoricalFS!C34 -> 0.19562616 | D15: =HistoricalFS!D34 -> 0.18764729 | E15: =HistoricalFS!E34 -> 0.18064401 | F15: =HistoricalFS!F34 -> 0.18606064 | G15: =HistoricalFS!G34 -> 0.17747803 | H15: =HistoricalFS!H34 -> 0.18666439 | I15: =HistoricalFS!I34 -> 0.17955818 | J15: =HistoricalFS!J34 -> 0.17233365 | ... L15: =HistoricalFS!L34 -> 0.17560041
B17: Return on Capital Employed | C17: =(HistoricalFS!C18-HistoricalFS!C24)/(SUM('Data Sheet'!B57:B59)) -> 0.40367654 | D17: =(HistoricalFS!D18-HistoricalFS!D24)/(SUM('Data Sheet'!C57:C59)) -> 0.35055432 | E17: =(HistoricalFS!E18-HistoricalFS!E24)/(SUM('Data Sheet'!D57:D59)) -> 0.35727086 | F17: =(HistoricalFS!F18-HistoricalFS!F24)/(SUM('Data Sheet'!E57:E59)) -> 0.41839836 | G17: =(HistoricalFS!G18-HistoricalFS!G24)/(SUM('Data Sheet'!F57:F59)) -> 0.41798483 | H17: =(HistoricalFS!H18-HistoricalFS!H24)/(SUM('Data Sheet'!G57:G59)) -> 0.45083202 | I17: =(HistoricalFS!I18-HistoricalFS!I24)/(SUM('Data Sheet'!H57:H59)) -> 0.499737 | J17: =(HistoricalFS!J18-HistoricalFS!J24)/(SUM('Data Sheet'!I57:I59)) -> 0.552807 | ... L17: =(HistoricalFS!L18-HistoricalFS!L24)/(SUM('Data Sheet'!K57:K59)) -> 0.59689096
B18: Return on Equity% | C18: =HistoricalFS!C33/SUM('Data Sheet'!B57:B58) -> 0.29904885 | D18: =HistoricalFS!D33/SUM('Data Sheet'!C57:C58) -> 0.25675644 | E18: =HistoricalFS!E33/SUM('Data Sheet'!D57:D58) -> 0.26123015 | F18: =HistoricalFS!F33/SUM('Data Sheet'!E57:E58) -> 0.30466427 | G18: =HistoricalFS!G33/SUM('Data Sheet'!F57:F58) -> 0.33111048 | H18: =HistoricalFS!H33/SUM('Data Sheet'!G57:G58) -> 0.35456365 | I18: =HistoricalFS!I33/SUM('Data Sheet'!H57:H58) -> 0.38626191 | J18: =HistoricalFS!J33/SUM('Data Sheet'!I57:I58) -> 0.42968681 | ... L18: =HistoricalFS!L33/SUM('Data Sheet'!K57:K58) -> 0.47316265
B21: Debtor Turnover Ratio | C21: =HistoricalFS!C6/HistoricalFS!C59 -> 4.513189 | D21: =HistoricalFS!D6/HistoricalFS!D59 -> 5.2158111 | E21: =HistoricalFS!E6/HistoricalFS!E59 -> 4.9354127 | F21: =HistoricalFS!F6/HistoricalFS!F59 -> 5.3559204 | G21: =HistoricalFS!G6/HistoricalFS!G59 -> 5.1404756 | H21: =HistoricalFS!H6/HistoricalFS!H59 -> 5.4581934 | I21: =HistoricalFS!I6/HistoricalFS!I59 -> 4.5863191 | J21: =HistoricalFS!J6/HistoricalFS!J59 -> 4.5133122 | ... L21: =HistoricalFS!L6/HistoricalFS!L59 -> 4.324154
B22: Creditor Turnover Ratio | C22: =HistoricalFS!C6/HistoricalFS!C50 -> 6.4007305 | D22: =HistoricalFS!D6/HistoricalFS!D50 -> 7.4520531 | E22: =HistoricalFS!E6/HistoricalFS!E50 -> 6.2327983 | F22: =HistoricalFS!F6/HistoricalFS!F50 -> 6.0043045 | G22: =HistoricalFS!G6/HistoricalFS!G50 -> 5.6401696 | H22: =HistoricalFS!H6/HistoricalFS!H50 -> 4.5905659 | I22: =HistoricalFS!I6/HistoricalFS!I50 -> 4.3613164 | J22: =HistoricalFS!J6/HistoricalFS!J50 -> 5.0385054 | ... L22: =HistoricalFS!L6/HistoricalFS!L50 -> 4.6847581
B23: Fixed Asset Turnover | C23: =HistoricalFS!C6/HistoricalFS!C53 -> 9.2276202 | D23: =HistoricalFS!D6/HistoricalFS!D53 -> 10.081702 | E23: =HistoricalFS!E6/HistoricalFS!E53 -> 10.281801 | F23: =HistoricalFS!F6/HistoricalFS!F53 -> 11.91725 | G23: =HistoricalFS!G6/HistoricalFS!G53 -> 7.4994744 | H23: =HistoricalFS!H6/HistoricalFS!H53 -> 7.8101422 | I23: =HistoricalFS!I6/HistoricalFS!I53 -> 9.0033806 | J23: =HistoricalFS!J6/HistoricalFS!J53 -> 10.98991 | ... L23: =HistoricalFS!L6/HistoricalFS!L53 -> 11.075522
B24: Capital Turnover Ratio | C24: =HistoricalFS!C6/SUM(HistoricalFS!C47:C48) -> 1.5286751 | D24: =HistoricalFS!D6/SUM(HistoricalFS!D47:D48) -> 1.3682929 | E24: =HistoricalFS!E6/SUM(HistoricalFS!E47:E48) -> 1.4461047 | F24: =HistoricalFS!F6/SUM(HistoricalFS!F47:F48) -> 1.6374461 | G24: =HistoricalFS!G6/SUM(HistoricalFS!G47:G48) -> 1.865642 | H24: =HistoricalFS!H6/SUM(HistoricalFS!H47:H48) -> 1.8994713 | I24: =HistoricalFS!I6/SUM(HistoricalFS!I47:I48) -> 2.1511796 | J24: =HistoricalFS!J6/SUM(HistoricalFS!J47:J48) -> 2.4933425 | ... L24: =HistoricalFS!L6/SUM(HistoricalFS!L47:L48) -> 2.6945418
B25: Debtor Days | C25: ='Data Sheet'!B60/'Data Sheet'!B42*100 -> 28.584901 | D25: ='Data Sheet'!C67/'Data Sheet'!C17*365 -> 69.979528 | E25: ='Data Sheet'!D67/'Data Sheet'!D17*365 -> 73.955314 | F25: ='Data Sheet'!E67/'Data Sheet'!E17*365 -> 68.148884 | G25: ='Data Sheet'!F67/'Data Sheet'!F17*365 -> 71.005104 | H25: ='Data Sheet'!G67/'Data Sheet'!G17*365 -> 66.871943 | I25: ='Data Sheet'!H67/'Data Sheet'!H17*365 -> 79.58452 | J25: ='Data Sheet'!I67/'Data Sheet'!I17*365 -> 80.87187 | K25: ='Data Sheet'!J67/'Data Sheet'!J17*365 -> 81.179632 | L25: ='Data Sheet'!K67/'Data Sheet'!K17*365 -> 84.409574
B28: Curent Ratio | C28: =SUM(HistoricalFS!C62)/HistoricalFS!C50 -> 1.8190762 | D28: =SUM(HistoricalFS!D62)/HistoricalFS!D50 -> 1.6921668 | E28: =SUM(HistoricalFS!E62)/HistoricalFS!E50 -> 1.6267531 | F28: =SUM(HistoricalFS!F62)/HistoricalFS!F50 -> 1.6481778 | G28: =SUM(HistoricalFS!G62)/HistoricalFS!G50 -> 1.4447479 | H28: =SUM(HistoricalFS!H62)/HistoricalFS!H50 -> 1.1021139 | I28: =SUM(HistoricalFS!I62)/HistoricalFS!I50 -> 1.3658198 | J28: =SUM(HistoricalFS!J62)/HistoricalFS!J50 -> 1.3635328 | ... L28: =SUM(HistoricalFS!L62)/HistoricalFS!L50 -> 1.3674978
B29: Quick ratio | C29: =SUM(HistoricalFS!C62-HistoricalFS!C60)/HistoricalFS!C50 -> 1.8181336 | D29: =SUM(HistoricalFS!D62-HistoricalFS!D60)/HistoricalFS!D50 -> 1.6908402 | E29: =SUM(HistoricalFS!E62-HistoricalFS!E60)/HistoricalFS!E50 -> 1.6254367 | F29: =SUM(HistoricalFS!F62-HistoricalFS!F60)/HistoricalFS!F50 -> 1.6477678 | G29: =SUM(HistoricalFS!G62-HistoricalFS!G60)/HistoricalFS!G50 -> 1.4445682 | H29: =SUM(HistoricalFS!H62-HistoricalFS!H60)/HistoricalFS!H50 -> 1.1018902 | I29: =SUM(HistoricalFS!I62-HistoricalFS!I60)/HistoricalFS!I50 -> 1.3653649 | J29: =SUM(HistoricalFS!J62-HistoricalFS!J60)/HistoricalFS!J50 -> 1.362907 | ... L29: =SUM(HistoricalFS!L62-HistoricalFS!L60)/HistoricalFS!L50 -> 1.3671125
B30: Debt-to Equity | C30: =SUM(HistoricalFS!C49:C50)/(SUM('Data Sheet'!B57:B58)) -> 0.24227544 | D30: =SUM(HistoricalFS!D49:D50)/(SUM('Data Sheet'!C57:C58)) -> 0.18696499 | E30: =SUM(HistoricalFS!E49:E50)/(SUM('Data Sheet'!D57:D58)) -> 0.23491683 | F30: =SUM(HistoricalFS!F49:F50)/(SUM('Data Sheet'!E57:E58)) -> 0.27340518 | G30: =SUM(HistoricalFS!G49:G50)/(SUM('Data Sheet'!F57:F58)) -> 0.42794142 | H30: =SUM(HistoricalFS!H49:H50)/(SUM('Data Sheet'!G57:G58)) -> 0.50396261 | I30: =SUM(HistoricalFS!I49:I50)/(SUM('Data Sheet'!H57:H58)) -> 0.58094661 | J30: =SUM(HistoricalFS!J49:J50)/(SUM('Data Sheet'!I57:I58)) -> 0.57987924 | ... L30: =SUM(HistoricalFS!L49:L50)/(SUM('Data Sheet'!K57:K58)) -> 0.67428975

Sheet scenario analysis
E2: Final Scenario Table
C3: Scenario Analysis for | E3: TATA CONSULTANCY SERVICES LTD | L3: Senario Asumption
D4: Scenario | E4: Revenue | F4: COGS | G4: Net Profit | K4: Scenario | L4: Revenue Growth | M4: COGS Change | N4: Profit Margin
D5: Base | E5: 250000 | F5: =HistoricalFS!L9 -> 157436 | G5: =HistoricalFS!L33 -> 44835 | K5: Base | L5: 0.05 | M5: 0.12 | N5: 0.18
D7: Best | E7: 500000 | K7: Best | L7: 0.1 | M7: 0.15 | N7: 0.25
D9: Worst | E9: 150000 | K9: Worst | L9: 0.02 | M9: 0.05 | N9: 0.1

Sheet Financials 
B2: ='Data Sheet'!B1&" - "&'Data Sheet'!A17&" Forecast" -> TATA CONSULTANCY SERVICES LTD - Sales Forecast | J2: ='Data Sheet'!B1&" - "&HistoricalFS!B18&" Forecast" -> TATA CONSULTANCY SERVICES LTD - EBITDA Forecast | O2: ='Data Sheet'!B1&" - "&HistoricalFS!B36& "Forecast" -> TATA CONSULTANCY SERVICES LTD - No of Equity SharesForecast
B3: Year weight | C3: Year | D3: Sales | E3: Sales Growth | J3: Year weight | K3: Year | L3: Sales | M3: Sales Growth | O3: Year weight | P3: Year | Q3: Sales | R3: Sales Growth
B4: 1 | C4: 2013 | D4: {=TRANSPOSE('Data Sheet'!B17:K17)} -> 108646 | J4: 1 | K4: 2013 | L4: {=TRANSPOSE(HistoricalFS!C18:M18)} -> 30677 | O4: 1 | P4: 2013 | Q4: {=TRANSPOSE(HistoricalFS!C38:M38)} -> 53.931843
B5: =B4+1 -> 2 | C5: =C4+1 -> 2014 | D5: 117966 | E5: =D5/D4-1 -> 0.085783186 | J5: =J4+1 -> 2 | K5: =K4+1 -> 2014 | L5: 32311 | M5: =L5/L4-1 -> 0.053264661 | O5: =O4+1 -> 2 | P5: =P4+1 -> 2014 | Q5: 56.16991 | R5: =Q5/Q4-1 -> 0.041498071
B6: =B5+1 -> 3 | C6: =C5+1 -> 2015 | D6: 123104 | E6: =D6/D5-1 -> 0.043554923 | J6: =J5+1 -> 3 | K6: =K5+1 -> 2015 | L6: 32516 | M6: =L6/L5-1 -> 0.0063445885 | O6: =O5+1 -> 3 | P6: =P5+1 -> 2015 | Q6: 58.083895 | R6: =Q6/Q5-1 -> 0.034074907
B7: =B6+1 -> 4 | C7: =C6+1 -> 2016 | D7: 146463 | E7: =D7/D6-1 -> 0.18975013 | J7: =J6+1 -> 4 | K7: =K6+1 -> 2016 | L7: 39506 | M7: =L7/L6-1 -> 0.21497109 | O7: =O6+1 -> 4 | P7: =P6+1 -> 2016 | Q7: 72.622855 | R7: =Q7/Q6-1 -> 0.25030966
B8: =B7+1 -> 5 | C8: =C7+1 -> 2017 | D8: 156949 | E8: =D8/D7-1 -> 0.071594874 | J8: =J7+1 -> 5 | K8: =K7+1 -> 2017 | L8: 42109 | M8: =L8/L7-1 -> 0.065888726 | O8: =O7+1 -> 5 | P8: =P7+1 -> 2017 | Q8: 74.232491 | R8: =Q8/Q7-1 -> 0.022164324
B9: =B8+1 -> 6 | C9: =C8+1 -> 2018 | D9: 164177 | E9: =D9/D8-1 -> 0.046053177 | J9: =J8+1 -> 6 | K9: =K8+1 -> 2018 | L9: 46546 | M9: =L9/L8-1 -> 0.1053694 | O9: =O8+1 -> 6 | P9: =P8+1 -> 2018 | Q9: 82.847179 | R9: =Q9/Q8-1 -> 0.1160501
B10: =B9+1 -> 7 | C10: =C9+1 -> 2019 | D10: 191754 | E10: =D10/D9-1 -> 0.16797115 | J10: =J9+1 -> 7 | K10: =K9+1 -> 2019 | L10: 53057 | M10: =L10/L9-1 -> 0.13988313 | O10: =O9+1 -> 7 | P10: =P9+1 -> 2019 | Q10: 94.096909 | R10: =Q10/Q9-1 -> 0.13578893
B11: =B10+1 -> 8 | C11: =C10+1 -> 2020 | D11: 225458 | E11: =D11/D10-1 -> 0.17576687 | J11: =J10+1 -> 8 | K11: =K10+1 -> 2020 | L11: 59259 | M11: =L11/L10-1 -> 0.11689315 | O11: =O10+1 -> 8 | P11: =P10+1 -> 2020 | Q11: 106.18458 | R11: =Q11/Q10-1 -> 0.12845982
B12: =B11+1 -> 9 | C12: =C11+1 -> 2021 | D12: 240893 | E12: =D12/D11-1 -> 0.068460645 | J12: =J11+1 -> 9 | K12: =K11+1 -> 2021 | L12: 64296 | M12: =L12/L11-1 -> 0.084999747 | O12: =O11+1 -> 9 | P12: =P11+1 -> 2021 | Q12: 117.83809 | R12: =Q12/Q11-1 -> 0.10974768
B13: =B12+1 -> 10 | C13: =C12+1 -> 2022 | D13: 255324 | E13: =D13/D12-1 -> 0.059906265 | J13: =J12+1 -> 10 | K13: =K12+1 -> 2022 | L13: 67407 | M13: =L13/L12-1 -> 0.048385592 | O13: =O12+1 -> 10 | P13: =P12+1 -> 2022 | Q13: 123.91863 | R13: =Q13/Q12-1 -> 0.051600797
B14: =B13+1 -> 11 | C14: =C13+1 -> 2023 | D14: =FORECAST(B14,$D$4:$D$13,$B$4:$B$13) -> 267588.8 | E14: =D14/D13-1 -> 0.048036221 | J14: =J13+1 -> 11 | K14: =K13+1 -> 2023 | L14: =FORECAST(J14,$L$4:$L$13,$J$4:$J$13) -> 71210.733 | M14: =L14/L13-1 -> 0.056429352 | O14: =O13+1 -> 11 | P14: =P13+1 -> 2023 | Q14: =FORECAST(O14,$Q$4:$Q$13,$O$4:$O$13) -> 129.82926 | R14: =Q14/Q13-1 -> 0.047697661
B15: =B14+1 -> 12 | C15: =C14+1 -> 2024 | D15: =FORECAST(B15,$D$4:$D$13,$B$4:$B$13) -> 284773.42 | E15: =D15/D14-1 -> 0.064220245 | J15: =J14+1 -> 12 | K15: =K14+1 -> 2024 | L15: =FORECAST(J15,$L$4:$L$13,$J$4:$J$13) -> 75654.794 | M15: =L15/L14-1 -> 0.062407174 | O15: =O14+1 -> 12 | P15: =P14+1 -> 2024 | Q15: =FORECAST(O15,$Q$4:$Q$13,$O$4:$O$13) -> 138.16319 | R15: =Q15/Q14-1 -> 0.064191471
B16: =B15+1 -> 13 | C16: =C15+1 -> 2025 | D16: =FORECAST(B16,$D$4:$D$13,$B$4:$B$13) -> 301958.04 | E16: =D16/D15-1 -> 0.060344882 | J16: =J15+1 -> 13 | K16: =K15+1 -> 2025 | L16: =FORECAST(J16,$L$4:$L$13,$J$4:$J$13) -> 80098.855 | M16: =L16/L15-1 -> 0.058741295 | O16: =O15+1 -> 13 | P16: =P15+1 -> 2025 | Q16: =FORECAST(O16,$Q$4:$Q$13,$O$4:$O$13) -> 146.49712 | R16: =Q16/Q15-1 -> 0.060319475
B17: =B16+1 -> 14 | C17: =C16+1 -> 2026 | D17: =FORECAST(B17,$D$4:$D$13,$B$4:$B$13) -> 319142.65 | E17: =D17/D16-1 -> 0.056910617 | J17: =J16+1 -> 14 | K17: =K16+1 -> 2026 | L17: =FORECAST(J17,$L$4:$L$13,$J$4:$J$13) -> 84542.915 | M17: =L17/L16-1 -> 0.055482199 | O17: =O16+1 -> 14 | P17: =P16+1 -> 2026 | Q17: =FORECAST(O17,$Q$4:$Q$13,$O$4:$O$13) -> 154.83105 | R17: =Q17/Q16-1 -> 0.05688802
B18: =B17+1 -> 15 | C18: =C17+1 -> 2027 | D18: =FORECAST(B18,$D$4:$D$13,$B$4:$B$13) -> 336327.27 | E18: =D18/D17-1 -> 0.053846197 | J18: =J17+1 -> 15 | K18: =K17+1 -> 2027 | L18: =FORECAST(J18,$L$4:$L$13,$J$4:$J$13) -> 88986.976 | M18: =L18/L17-1 -> 0.052565737 | O18: =O17+1 -> 15 | P18: =P17+1 -> 2027 | Q18: =FORECAST(O18,$Q$4:$Q$13,$O$4:$O$13) -> 163.16498 | R18: =Q18/Q17-1 -> 0.053825967

Sheet Ratio Analysis
B2: ="Ratio Analysis of - "&'Data Sheet'!B1 -> Ratio Analysis of - TATA CONSULTANCY SERVICES LTD
B3: Years | C3: ='Data Sheet'!B16 -> 42460 | D3: ='Data Sheet'!C16 -> 42825 | E3: ='Data Sheet'!D16 -> 43190 | F3: ='Data Sheet'!E16 -> 43555 | G3: ='Data Sheet'!F16 -> 43921 | H3: ='Data Sheet'!G16 -> 44286 | I3: ='Data Sheet'!H16 -> 44651 | J3: ='Data Sheet'!I16 -> 45016 | ... L3: ='Data Sheet'!K16 -> 45747 | M3: LTM
B5: SalesGrowth
B6: GrossMargin
B7: EBITDA Growth
B8: EBIT Growth
B9: Net Profit Growth
B10: Dividend Growth
B12: Gross Margin
B13: Operating Margin
B14: EBITDA Margin
B15: EBIT Margin
B16: EBT Margin
B17: Net Profit Margin
... B43: CFO/Total Debt

Sheet Forecasting
B2: ='Data Sheet'!$B$1&" - "&'Data Sheet'!A17&" Forecasting" -> TATA CONSULTANCY SERVICES LTD - Sales Forecasting | G2: ='Data Sheet'!$B$1&" - "&'Data Sheet'!A34&" Forecasting" -> TATA CONSULTANCY SERVICES LTD - EBITDA Forecasting | L2: ='Data Sheet'!$B$1&" - "&HistoricalFS!B38&" Forecasting" -> TATA CONSULTANCY SERVICES LTD - Earnings per Share Forecasting
B3: Year Weight | C3: Year | D3: Sales | E3: Sales Growth | G3: Year Weight | H3: Year | I3: Sales | J3: Sales Growth | L3: Year Weight | M3: Year | N3: Sales | O3: Sales Growth
B4: 1 | C4: ='Data Sheet'!$B$16 -> 42460 | D4: {=TRANSPOSE('Data Sheet'!B17:K17)} -> 108646 | G4: 1 | H4: ='Data Sheet'!$B$16 -> 42460 | I4: {=TRANSPOSE('Data Sheet'!B34:K34)} -> 33693 | L4: 1 | M4: ='Data Sheet'!$B$16 -> 42460 | N4: {=TRANSPOSE(HistoricalFS!C38:L38)} -> 53.931843
B5: =B4+1 -> 2 | C5: =C4+365 -> 42825 | D5: 117966 | E5: =D5/D4-1 -> 0.085783186 | G5: =G4+1 -> 2 | H5: =H4+365 -> 42825 | I5: 36464 | J5: =I5/I4-1 -> 0.082242602 | L5: =L4+1 -> 2 | M5: =M4+365 -> 42825 | N5: 56.16991 | O5: =N5/N4-1 -> 0.041498071
B6: =B5+1 -> 3 | C6: =C5+365 -> 43190 | D6: 123104 | E6: =D6/D5-1 -> 0.043554923 | G6: =G5+1 -> 3 | H6: =H5+365 -> 43190 | I6: 36104 | J6: =I6/I5-1 -> -0.0098727512 | L6: =L5+1 -> 3 | M6: =M5+365 -> 43190 | N6: 58.083895 | O6: =N6/N5-1 -> 0.034074907
B7: =B6+1 -> 4 | C7: =C6+365 -> 43555 | D7: 146463 | E7: =D7/D6-1 -> 0.18975013 | G7: =G6+1 -> 4 | H7: =H6+365 -> 43555 | I7: 43727 | J7: =I7/I6-1 -> 0.21114004 | L7: =L6+1 -> 4 | M7: =M6+365 -> 43555 | N7: 72.622855 | O7: =N7/N6-1 -> 0.25030966
B8: =B7+1 -> 5 | C8: =C7+365 -> 43920 | D8: 156949 | E8: =D8/D7-1 -> 0.071594874 | G8: =G7+1 -> 5 | H8: =H7+365 -> 43920 | I8: 46594 | J8: =I8/I7-1 -> 0.065565898 | L8: =L7+1 -> 5 | M8: =M7+365 -> 43920 | N8: 74.232491 | O8: =N8/N7-1 -> 0.022164324
B9: =B8+1 -> 6 | C9: =C8+365 -> 44285 | D9: 164177 | E9: =D9/D8-1 -> 0.046053177 | G9: =G8+1 -> 6 | H9: =H8+365 -> 44285 | I9: 48330 | J9: =I9/I8-1 -> 0.037258016 | L9: =L8+1 -> 6 | M9: =M8+365 -> 44285 | N9: 82.847179 | O9: =N9/N8-1 -> 0.1160501
B10: =B9+1 -> 7 | C10: =C9+365 -> 44650 | D10: 191754 | E10: =D10/D9-1 -> 0.16797115 | G10: =G9+1 -> 7 | H10: =H9+365 -> 44650 | I10: 56953 | J10: =I10/I9-1 -> 0.1784192 | L10: =L9+1 -> 7 | M10: =M9+365 -> 44650 | N10: 94.096909 | O10: =N10/N9-1 -> 0.13578893
B11: =B10+1 -> 8 | C11: =C10+365 -> 45015 | D11: 225458 | E11: =D11/D10-1 -> 0.17576687 | G11: =G10+1 -> 8 | H11: =H10+365 -> 45015 | I11: 62552 | J11: =I11/I10-1 -> 0.098309132 | L11: =L10+1 -> 8 | M11: =M10+365 -> 45015 | N11: 106.18458 | O11: =N11/N10-1 -> 0.12845982
B12: =B11+1 -> 9 | C12: =C11+365 -> 45380 | D12: 240893 | E12: =D12/D11-1 -> 0.068460645 | G12: =G11+1 -> 9 | H12: =H11+365 -> 45380 | I12: 67569 | J12: =I12/I11-1 -> 0.080205269 | L12: =L11+1 -> 9 | M12: =M11+365 -> 45380 | N12: 117.83809 | O12: =N12/N11-1 -> 0.10974768
B13: =B12+1 -> 10 | C13: =C12+365 -> 45745 | D13: 255324 | E13: =D13/D12-1 -> 0.059906265 | G13: =G12+1 -> 10 | H13: =H12+365 -> 45745 | I13: 71125 | J13: =I13/I12-1 -> 0.052627684 | L13: =L12+1 -> 10 | M13: =M12+365 -> 45745 | N13: 123.91863 | O13: =N13/N12-1 -> 0.051600797
B14: =B13+1 -> 11 | C14: =C13+365 -> 46110 | D14: =FORECAST(B14,$D$4:$D$13,$B$4:$B$13) -> 267588.8 | E14: =D14/D13-1 -> 0.048036221 | G14: =G13+1 -> 11 | H14: =H13+365 -> 46110 | I14: =FORECAST(G14,$I$4:$I$13,$G$4:$G$13) -> 74587 | J14: =I14/I13-1 -> 0.048674868 | L14: =L13+1 -> 11 | M14: =M13+365 -> 46110 | N14: =FORECAST(L14,$N$4:$N$13,$L$4:$L$13) -> 129.82926 | O14: =N14/N13-1 -> 0.047697661
B15: =B14+1 -> 12 | C15: =C14+365 -> 46475 | D15: =FORECAST(B15,$D$4:$D$13,$B$4:$B$13) -> 284773.42 | E15: =D15/D14-1 -> 0.064220245 | G15: =G14+1 -> 12 | H15: =H14+365 -> 46475 | I15: =FORECAST(G15,$I$4:$I$13,$G$4:$G$13) -> 79000.8 | J15: =I15/I14-1 -> 0.059176532 | L15: =L14+1 -> 12 | M15: =M14+365 -> 46475 | N15: =FORECAST(L15,$N$4:$N$13,$L$4:$L$13) -> 138.16319 | O15: =N15/N14-1 -> 0.064191471
B16: =B15+1 -> 13 | C16: =C15+365 -> 46840 | D16: =FORECAST(B16,$D$4:$D$13,$B$4:$B$13) -> 301958.04 | E16: =D16/D15-1 -> 0.060344882 | G16: =G15+1 -> 13 | H16: =H15+365 -> 46840 | I16: =FORECAST(G16,$I$4:$I$13,$G$4:$G$13) -> 83414.6 | J16: =I16/I15-1 -> 0.05587032 | L16: =L15+1 -> 13 | M16: =M15+365 -> 46840 | N16: =FORECAST(L16,$N$4:$N$13,$L$4:$L$13) -> 146.49712 | O16: =N16/N15-1 -> 0.060319475
B17: =B16+1 -> 14 | C17: =C16+365 -> 47205 | D17: =FORECAST(B17,$D$4:$D$13,$B$4:$B$13) -> 319142.65 | E17: =D17/D16-1 -> 0.056910617 | G17: =G16+1 -> 14 | H17: =H16+365 -> 47205 | I17: =FORECAST(G17,$I$4:$I$13,$G$4:$G$13) -> 87828.4 | J17: =I17/I16-1 -> 0.052913998 | L17: =L16+1 -> 14 | M17: =M16+365 -> 47205 | N17: =FORECAST(L17,$N$4:$N$13,$L$4:$L$13) -> 154.83105 | O17: =N17/N16-1 -> 0.05688802
B18: =B17+1 -> 15 | C18: =C17+365 -> 47570 | D18: =FORECAST(B18,$D$4:$D$13,$B$4:$B$13) -> 336327.27 | E18: =D18/D17-1 -> 0.053846197 | G18: =G17+1 -> 15 | H18: =H17+365 -> 47570 | I18: =FORECAST(G18,$I$4:$I$13,$G$4:$G$13) -> 92242.2 | J18: =I18/I17-1 -> 0.050254815 | L18: =L17+1 -> 15 | M18: =M17+365 -> 47570 | N18: =FORECAST(L18,$N$4:$N$13,$L$4:$L$13) -> 163.16498 | O18: =N18/N17-1 -> 0.053825967

Sheet Data>
D5: Sales Comapriosn

Sheet Data Sheet
A1: COMPANY NAME | B1: TATA CONSULTANCY SERVICES LTD | E1: =IF(B2<>B3, "A NEW VERSION OF THE WORKSHEET IS AVAILABLE", "")
A2: LATEST VERSION | B2: 2.1 | E2: PLEASE DO NOT MAKE ANY CHANGES TO THIS SHEET
A3: CURRENT VERSION | B3: 2.1
A5: META
A6: Number of shares | B6: =IF(B9>0, B9/B8, 0) -> 361.80875
A7: Face Value | B7: 1
A8: Current Price | B8: 3106
A9: Market Capitalization | B9: 1123778
A15: PROFIT & LOSS | B15: =B26+B34 -> 35581 | K15: =K17-K18-K20-K21-K22-K23-K19 -> 77159
A16: Report Date | B16: 42460 | C16: 42825 | D16: 43190 | E16: 43555 | F16: 43921 | G16: 44286 | H16: 44651 | I16: 45016 | J16: 45382 | K16: 45747
A17: Sales | B17: 108646 | C17: 117966 | D17: 123104 | E17: 146463 | F17: 156949 | G17: 164177 | H17: 191754 | I17: 225458 | J17: 240893 | K17: 255324
A18: Raw Material Cost | C18: 94 | D18: 86 | E18: 40 | F18: 18 | G18: 14 | H18: 29 | I18: 37 | J18: 42 | K18: 49
A19: Change in Inventory | C19: 1
A20: Power and Fuel
A21: Other Mfr. Exp | B21: 2571 | C21: 2715 | D21: 2614 | E21: 2230 | F21: 1887 | G21: 1448 | H21: 1134 | I21: 1844 | J21: 3660 | K21: 11599
A22: Employee Cost | B22: 55348 | C22: 61621 | D22: 66396 | E22: 78246 | F22: 85952 | G22: 91814 | H22: 107554 | I22: 127522 | J22: 140131 | K22: 145788
A23: Selling and admin | B23: 15589 | C23: 16392 | D23: 16808 | E23: 20387 | F23: 20527 | G23: 18322 | H23: 23187 | I23: 28913 | J23: 24151 | K23: 20729
A24: Other Expenses | B24: 4461 | C24: 4834 | D24: 4684 | E24: 6054 | F24: 6456 | G24: 6033 | H24: 6793 | I24: 7883 | J24: 8613 | K24: 9752
A25: Other Income | B25: 3084 | C25: 4221 | D25: 3642 | E25: 4311 | F25: 4592 | G25: 1916 | H25: 4018 | I25: 3449 | J25: 3464 | K25: 3962
A26: Depreciation | B26: 1888 | C26: 1987 | D26: 2014 | E26: 2056 | F26: 3529 | G26: 4065 | H26: 4604 | I26: 5022 | J26: 4985 | K26: 5242
A27: Interest | B27: 33 | C27: 32 | D27: 52 | E27: 198 | F27: 924 | G27: 637 | H27: 784 | I27: 779 | J27: 778 | K27: 796
A28: Profit before tax | B28: 31840 | C28: 34513 | D28: 34092 | E28: 41563 | F28: 42248 | G28: 43760 | H28: 51687 | I28: 56907 | J28: 61997 | K28: 65331
A29: Tax | B29: 7502 | C29: 8156 | D29: 8212 | E29: 10001 | F29: 9801 | G29: 11198 | H29: 13238 | I29: 14604 | J29: 15898 | K29: 16534
A30: Net profit | B30: 24270 | C30: 26289 | D30: 25826 | E30: 31472 | F30: 32340 | G30: 32430 | H30: 38327 | I30: 42147 | J30: 45908 | K30: 48553
A31: Dividend Amount | B31: 8569.5 | C31: 9259 | D31: 9550 | E31: 11250 | F31: 27375 | G31: 14060 | H31: 15738 | I31: 42090 | J31: 26426 | K31: 45612
A32: Effective Tax Rate | B32: =B29/B28 -> 0.23561558 | C32: =C29/C28 -> 0.23631675 | D32: =D29/D28 -> 0.24087763 | E32: =E29/E28 -> 0.24062267 | F32: =F29/F28 -> 0.23198731 | G32: =G29/G28 -> 0.2558958 | H32: =H29/H28 -> 0.25611856 | I32: =I29/I28 -> 0.25662924 | ... K32: =K29/K28 -> 0.25308047
A34: EBITDA | B34: =+B30+B29+B27+B26 -> 33693 | C34: =+C30+C29+C27+C26 -> 36464 | D34: =+D30+D29+D27+D26 -> 36104 | E34: =+E30+E29+E27+E26 -> 43727 | F34: =+F30+F29+F27+F26 -> 46594 | G34: =+G30+G29+G27+G26 -> 48330 | H34: =+H30+H29+H27+H26 -> 56953 | I34: =+I30+I29+I27+I26 -> 62552 | ... K34: =+K30+K29+K27+K26 -> 71125
A40: Quarters
A41: Report Date | B41: 45107 | C41: 45199 | D41: 45291 | E41: 45382 | F41: 45473 | G41: 45565 | H41: 45657 | I41: 45747 | J41: 45838 | K41: 45930
A42: Sales | B42: 59381 | C42: 59692 | D42: 60583 | E42: 61237 | F42: 62613 | G42: 64259 | H42: 63973 | I42: 64479 | J42: 63437 | K42: 65799
A43: Expenses | B43: 44383 | C43: 43946 | D43: 44195 | E43: 44073 | F43: 45951 | G43: 47528 | H43: 46939 | I43: 47499 | J43: 46562 | K43: 47821
A44: Other Income | B44: 1397 | C44: 1006 | D44: -96 | E44: 1157 | F44: 962 | G44: 729 | H44: 1243 | I44: 1028 | J44: 1660 | K44: -268
A45: Depreciation | B45: 1243 | C45: 1263 | D45: 1233 | E45: 1246 | F45: 1220 | G45: 1266 | H45: 1377 | I45: 1379 | J45: 1361 | K45: 1413
A46: Interest | B46: 163 | C46: 159 | D46: 230 | E46: 226 | F46: 173 | G46: 162 | H46: 234 | I46: 227 | J46: 195 | K46: 229
A47: Profit before tax | B47: 14989 | C47: 15330 | D47: 14829 | E47: 16849 | F47: 16231 | G47: 16032 | H47: 16666 | I47: 16402 | J47: 16979 | K47: 16068
A48: Tax | B48: 3869 | C48: 3950 | D48: 3732 | E48: 4347 | F48: 4126 | G48: 4077 | H48: 4222 | I48: 4109 | J48: 4160 | K48: 3937
A49: Net profit | B49: 11074 | C49: 11342 | D49: 11058 | E49: 12434 | F49: 12040 | G49: 11909 | H49: 12380 | I49: 12224 | J49: 12760 | K49: 12075
A50: Operating Profit | B50: 14998 | C50: 15746 | D50: 16388 | E50: 17164 | F50: 16662 | G50: 16731 | H50: 17034 | I50: 16980 | J50: 16875 | K50: 17978
A51: EBITDA | B51: =B49+B48+B46+B45 -> 16349 | C51: =C49+C48+C46+C45 -> 16714 | D51: =D49+D48+D46+D45 -> 16253 | E51: =E49+E48+E46+E45 -> 18253 | F51: =F49+F48+F46+F45 -> 17559 | G51: =G49+G48+G46+G45 -> 17414 | H51: =H49+H48+H46+H45 -> 18213 | I51: =I49+I48+I46+I45 -> 17939 | ... K51: =K49+K48+K46+K45 -> 17654
A55: BALANCE SHEET
...

Sheet Peer Analysis
B2: ="Peer Analysis - "&'Data Sheet'!B1 -> Peer Analysis - TATA CONSULTANCY SERVICES LTD
B3: Ratios

Sheet Charts
B3: Revenue Comparison
